Workbook

Sheet Sheet1
C1: D'Mart Dataset
A3: Date | B3: Invoice_ID | C3: Customer_ID | D3: Product_Name | E3: Product_Category | F3: Quantity | G3: Unit_Price | H3: Discount | I3: Payment_Method | J3: Store_Location
A4: 46204 | B4: INV0001 | C4: CUST112 | D4: Soap | E4: Stationery | F4: 2 | G4: 100 | H4: 20 | I4: Cash | J4: Aurangabad
A5: 46205 | B5: INV0002 | C5: CUST108 | D5: Soap | E5: Grocery | F5: 3 | G5: 100 | H5: 10 | I5: Cash | J5: Pune
A6: 46206 | B6: INV0003 | C6: CUST104 | D6: Pen | E6: Stationery | F6: 2 | G6: 400 | H6: 20 | I6: Card | J6: Nashik
A7: 46207 | B7: INV0004 | C7: CUST113 | D7: Notebook | E7: Stationery | F7: 2 | G7: 100 | H7: 0 | I7: Card | J7: Pune
A8: 46208 | B8: INV0005 | C8: CUST114 | D8: Shoes | E8: Clothing | F8: 1 | G8: 100 | H8: 0 | I8: Cash | J8: Mumbai
A9: 46209 | B9: INV0006 | C9: CUST113 | D9: Shoes | E9: Stationery | F9: 5 | G9: 50 | H9: 10 | I9: Cash | J9: Nagpur
A10: 46210 | B10: INV0007 | C10: CUST110 | D10: Milk 1L | E10: Home | F10: 4 | G10: 100 | H10: 0 | I10: Card | J10: Nashik
A11: 46211 | B11: INV0008 | C11: CUST108 | D11: Mixer | E11: Electronics | F11: 1 | G11: 400 | H11: 0 | I11: Upi | J11: Pune
A12: 46212 | B12: INV0009 | C12: CUST103 | D12: Milk 1L | E12: Home | F12: 1 | G12: 200 | H12: 10 | I12: Upi | J12: Nagpur
A13: 46213 | B13: INV0010 | C13: CUST120 | D13: Soap | E13: Electronics | F13: 5 | G13: 100 | H13: 20 | I13: Upi | J13: Mumbai
A14: 46214 | B14: INV0011 | C14: CUST111 | D14: Soap | E14: Clothing | F14: 4 | G14: 400 | H14: 10 | I14: Card | J14: Pune
A15: 46215 | B15: INV0012 | C15: CUST102 | D15: Mobile Phone | E15: Stationery | F15: 2 | G15: 20000 | H15: 0 | I15: Cash | J15: Aurangabad
A16: 46216 | B16: INV0013 | C16: CUST119 | D16: Mobile Phone | E16: Clothing | G16: 15000 | H16: 0 | I16: Cash | J16: Mumbai
A17: 46217 | B17: INV0014 | C17: CUST118 | D17: Milk 1L | E17: Electronics | F17: 1 | G17: 50 | H17: 0 | I17: Cash | J17: Aurangabad
A18: 46218 | B18: INV0015 | C18: CUST114 | D18: Rice 5Kg | E18: Stationery | F18: 5 | G18: 400 | H18: 0 | I18: Cash | J18: Mumbai
A19: 46219 | B19: INV0016 | C19: CUST103 | D19: T-Shirt | E19: Stationery | F19: 1 | G19: 20000 | H19: 10 | I19: Card | J19: Nagpur
A20: 46220 | B20: INV0017 | C20: CUST118 | D20: Soap | E20: Grocery | F20: 4 | G20: 400 | H20: 0 | I20: Upi | J20: Nashik
A21: 46221 | B21: INV0018 | C21: CUST108 | D21: Milk 1L | E21: Stationery | G21: 400 | H21: 20 | I21: Upi | J21: Nagpur
A22: 46222 | B22: INV0019 | C22: CUST101 | D22: Soap | E22: Stationery | F22: 2 | G22: 100 | H22: 0 | I22: Card | J22: Pune
A23: 46223 | B23: INV0020 | C23: CUST112 | D23: Mixer | E23: Stationery | F23: 2 | G23: 450 | H23: 20 | I23: Card | J23: Pune
A24: 46224 | B24: INV0021 | C24: CUST111 | D24: Shoes | E24: Clothing | G24: 100 | H24: 20 | I24: Upi | J24: Nagpur
A25: 46225 | B25: INV0022 | C25: CUST105 | D25: Milk 1L | E25: Stationery | F25: 2 | G25: 15000 | H25: 0 | I25: Upi | J25: Nashik
A26: 46226 | B26: INV0023 | C26: CUST118 | D26: Soap | E26: Home | F26: 2 | G26: 450 | H26: 20 | I26: Upi | J26: Aurangabad
A27: 46227 | B27: INV0024 | C27: CUST111 | D27: Mixer | E27: Stationery | F27: 1 | G27: 200 | H27: 10 | I27: Card | J27: Pune
A28: 46228 | B28: INV0025 | C28: CUST108 | D28: Milk 1L | E28: Electronics | F28: =COUNT(F21) -> 0 | G28: 100 | H28: 0 | I28: Cash | J28: Pune
A29: 46229 | B29: INV0026 | C29: CUST108 | D29: Shoes | E29: Electronics | F29: 1 | G29: 450 | H29: 20 | I29: Upi | J29: Pune
A30: 46230 | B30: INV0027 | C30: CUST106 | D30: Soap | E30: Stationery | F30: 4 | G30: 100 | H30: 20 | I30: Cash | J30: Nashik
A31: 46231 | B31: INV0028 | C31: CUST106 | D31: Mobile Phone | E31: Clothing | F31: 1 | G31: 15000 | H31: 10 | I31: Card | J31: Pune
A32: 46232 | B32: INV0029 | C32: CUST106 | D32: Rice 5Kg | E32: Stationery | F32: 5 | G32: 200 | H32: 10 | I32: Card | J32: Pune
A33: 46233 | B33: INV0030 | C33: CUST106 | D33: Tv | E33: Grocery | F33: 5 | G33: 50 | H33: 0 | I33: Upi | J33: Nagpur
B34: INV0031 | C34: CUST117 | D34: Shoes | E34: Clothing | F34: 2 | G34: 400 | H34: 0 | I34: Cash | J34: Aurangabad
A35: 46235 | B35: INV0032 | C35: CUST100 | D35: Mixer | E35: Electronics | F35: 5 | G35: 100 | H35: 0 | I35: Card | J35: Pune
A36: 46236 | B36: INV0033 | C36: CUST104 | D36: Pen | E36: Clothing | F36: 5 | G36: 100 | H36: 10 | I36: Card | J36: Mumbai
A37: 46237 | B37: INV0034 | C37: CUST116 | D37: Notebook | E37: Grocery | F37: 5 | G37: 450 | H37: 0 | I37: Card | J37: Nashik
A38: 46238 | B38: INV0035 | C38: CUST113 | D38: Pen | E38: Electronics | F38: 5 | G38: 100 | H38: 20 | I38: Card | J38: Nashik
A39: 46239 | B39: INV0036 | C39: CUST115 | D39: Mobile Phone | E39: Clothing | F39: 2 | G39: 200 | H39: 20 | I39: Card | J39: Aurangabad
A40: 46240 | B40: INV0037 | C40: CUST105 | D40: Mixer | E40: Electronics | F40: 2 | G40: 450 | H40: 0 | I40: Cash | J40: Nagpur
A41: 46241 | B41: INV0038 | C41: CUST111 | D41: Mixer | E41: Home | G41: 20000 | H41: 0 | I41: Upi | J41: Nagpur
...

Sheet Sheet2
A1: EDA
A3: Unit price | B3: values | D3: Discount | E3: values
A4: sum | B4: =SUM(Sheet1!G4:G153) -> 687150 | D4: sum | E4: =SUM(Sheet1!H4:H153) -> 1170
A5: min | B5: =MIN(Sheet1!G4:G153) -> 50 | D5: min | E5: =MIN(Sheet1!H4:H153) -> 0
A6: max | B6: =MAX(Sheet1!G4:G153) -> 20000 | D6: max | E6: =MAX(Sheet1!H4:H153) -> 20
A7: ava | B7: =AVERAGE(Sheet1!G4:G153) -> 4581 | D7: ava | E7: =AVERAGE(Sheet1!H4:H153) -> 7.8
A8: mean | B8: 4581 | D8: mean | E8: 4581
A9: mode | B9: {=MODE(Sheet1!G4:G153)} -> 200 | D9: mode | E9: {=MODE(Sheet1!H4:H153)} -> 0
A10: medium | B10: =MEDIAN(Sheet1!G4:G153) -> 400 | D10: medium | E10: =MEDIAN(Sheet1!H4:H153) -> 5
A11: sd | B11: =STDEV(Sheet1!G4:G153) -> 7711.8963 | D11: sd | E11: =STDEV(Sheet1!H4:H153) -> 8.5820165
A14: Pivote colume
E15: Total order
A16: Product name | B16: Sales price | C16: Quantity
A17: Milk 1L | B17: =SUM(Sheet1!G10:G145) -> 625250 | C17: =SUM(Sheet1!F10:F145) -> 322 | E17: Order | F17: 150
A18: Mixer | B18: =SUM(Sheet1!G11:G140) -> 609650 | C18: =SUM(Sheet1!F11:F140) -> 306
A19: Mobile Phone | B19: =SUM(Sheet1!G15:G147) -> 624150 | C19: =SUM(Sheet1!F15:F147) -> 313
A20: Notebook | B20: =SUM(Sheet1!G7:G136) -> 594550 | C20: =SUM(Sheet1!F7:F136) -> 305
A21: Pen | B21: =SUM(Sheet1!G6:G150) -> 666400 | C21: =SUM(Sheet1!F6:F150) -> 348
A22: Rice 5Kg | B22: =SUM(Sheet1!G18:G153) -> 650050 | C22: =SUM(Sheet1!F18:F153) -> 325
A23: Shoes | B23: =SUM(Sheet1!G8:G124) -> 571150 | C23: =SUM(Sheet1!F8:F124) -> 277
A24: Soap | B24: =SUM(Sheet1!G4:G149) -> 646600 | C24: =SUM(Sheet1!F4:F149) -> 351
A25: T-Shirt | B25: =SUM(Sheet1!G19:G148) -> 608700 | C25: =SUM(Sheet1!F19:F148) -> 310
A26: Tv | B26: =SUM(Sheet1!G33:G152) -> 576700 | C26: =SUM(Sheet1!F33:F152) -> 295
